Traceback (most recent call last):
  File "C:\Users\LAB SISTER\AppData\Local\Programs\Python\Python312\Lib\site-packages\jupyter_cache\executors\utils.py", line 58, in single_nb_execution
    executenb(
  File "C:\Users\LAB SISTER\AppData\Local\Programs\Python\Python312\Lib\site-packages\nbclient\client.py", line 1314, in execute
    return NotebookClient(nb=nb, resources=resources, km=km, **kwargs).execute()
           ^^^^^^^^^^^^^^^^^^^^^^^^^^^^^^^^^^^^^^^^^^^^^^^^^^^^^^^^^^^^^^^^^^^^^
  File "C:\Users\LAB SISTER\AppData\Roaming\Python\Python312\site-packages\jupyter_core\utils\__init__.py", line 165, in wrapped
    return loop.run_until_complete(inner)
           ^^^^^^^^^^^^^^^^^^^^^^^^^^^^^^
  File "C:\Users\LAB SISTER\AppData\Local\Programs\Python\Python312\Lib\asyncio\base_events.py", line 685, in run_until_complete
    return future.result()
           ^^^^^^^^^^^^^^^
  File "C:\Users\LAB SISTER\AppData\Local\Programs\Python\Python312\Lib\site-packages\nbclient\client.py", line 709, in async_execute
    await self.async_execute_cell(
  File "C:\Users\LAB SISTER\AppData\Local\Programs\Python\Python312\Lib\site-packages\nbclient\client.py", line 1062, in async_execute_cell
    await self._check_raise_for_error(cell, cell_index, exec_reply)
  File "C:\Users\LAB SISTER\AppData\Local\Programs\Python\Python312\Lib\site-packages\nbclient\client.py", line 918, in _check_raise_for_error
    raise CellExecutionError.from_cell_and_msg(cell, exec_reply_content)
nbclient.exceptions.CellExecutionError: An error occurred while executing the following cell:
------------------
print(df['isi'][0])
------------------


[1;31m---------------------------------------------------------------------------[0m
[1;31mKeyError[0m                                  Traceback (most recent call last)
Cell [1;32mIn[9], line 1[0m
[1;32m----> 1[0m [38;5;28mprint[39m([43mdf[49m[43m[[49m[38;5;124;43m'[39;49m[38;5;124;43misi[39;49m[38;5;124;43m'[39;49m[43m][49m[[38;5;241m0[39m])

File [1;32m~\AppData\Local\Programs\Python\Python312\Lib\site-packages\pandas\core\frame.py:4090[0m, in [0;36mDataFrame.__getitem__[1;34m(self, key)[0m
[0;32m   4088[0m [38;5;28;01mif[39;00m [38;5;28mself[39m[38;5;241m.[39mcolumns[38;5;241m.[39mnlevels [38;5;241m>[39m [38;5;241m1[39m:
[0;32m   4089[0m     [38;5;28;01mreturn[39;00m [38;5;28mself[39m[38;5;241m.[39m_getitem_multilevel(key)
[1;32m-> 4090[0m indexer [38;5;241m=[39m [38;5;28;43mself[39;49m[38;5;241;43m.[39;49m[43mcolumns[49m[38;5;241;43m.[39;49m[43mget_loc[49m[43m([49m[43mkey[49m[43m)[49m
[0;32m   4091[0m [38;5;28;01mif[39;00m is_integer(indexer):
[0;32m   4092[0m     indexer [38;5;241m=[39m [indexer]

File [1;32m~\AppData\Local\Programs\Python\Python312\Lib\site-packages\pandas\core\indexes\range.py:417[0m, in [0;36mRangeIndex.get_loc[1;34m(self, key)[0m
[0;32m    415[0m         [38;5;28;01mraise[39;00m [38;5;167;01mKeyError[39;00m(key) [38;5;28;01mfrom[39;00m [38;5;21;01merr[39;00m
[0;32m    416[0m [38;5;28;01mif[39;00m [38;5;28misinstance[39m(key, Hashable):
[1;32m--> 417[0m     [38;5;28;01mraise[39;00m [38;5;167;01mKeyError[39;00m(key)
[0;32m    418[0m [38;5;28mself[39m[38;5;241m.[39m_check_indexing_error(key)
[0;32m    419[0m [38;5;28;01mraise[39;00m [38;5;167;01mKeyError[39;00m(key)

[1;31mKeyError[0m: 'isi'

